Workbook

Sheet New Item Fetch Sheet
A1: PO References | B1: LPO No | C1: LPO Date | D1: Supplier Name | E1: New Item Code | F1: New Item Name | G1: Item Group | H1: Qty | I1: Unit Price | J1: UOM | K1: Warehouse/Project
A2: MRG-LPO-00022 | B2: 1 | C2: 4th September 2025 | D2: AJMAN GAS LLC | E2: PROPANE HIGH PRESSURE REGULATOR WITH GUAGE | F2: PROPANE HIGH PRESSURE REGULATOR WITH GUAGE | G2: WATERPROOFING GASS | H2: 1 | I2: 200 | J2: Nos | K2: Stores - MRG | L2: {=IFERROR(TOCOL(TEXTSPLIT(_xlfn.TEXTJOIN(CHAR(10),TRUE,'Main Sheet'!L2:L5000),,CHAR(10),TRUE),1),"")}
E3: HIGH PRESSURE REGULATOR | F3: HIGH PRESSURE REGULATOR | G3: WATERPROOFING GASS | H3: 1 | I3: 160 | J3: Nos
E4: CP-WATERPRROFING_GAS_(22KG) | F4: WATERPRROFING GAS (22KG) | G4: WATERPROOFING GASS | H4: 14 | I4: 110 | J4: Nos
A5: MRG-LPO-00079 | B5: 2 | D5: AJMAN GAS LLC | E5: CP-WATERPRROFING_GAS_(22KG) | F5: WATERPRROFING GAS (22KG) | G5: WATERPROOFING GASS | H5: 272 | I5: 126 | J5: Nos
A6: MRG-LPO-00610 | B6: 3 | D6: Al Gurg Fosroc LLC | E6: CP-NITOCOTE_CM210_GREY_(_PART_A_15KG+_PART_B_5KG) | F6: NITOCOTE CM210 GREY ( PART A 15KG+ PART B 5KG) | G6: CEMENTITIOUS COATING | H6: 150 | I6: 66 | J6: Nos
A7: MRG-LPO-00133 | B7: 4 | D7: Al Nawras Printing Press Services | E7: CP-STICKER_10_X_5_CM | F7: STICKER 10 X 5 CM | G7: PRINTING & STATIONERY | H7: 60 | I7: 0.5 | J7: Nos
E8: STICKER 20 X 15 CM | F8: STICKER 20 X 15 CM | G8: PRINTING & STATIONERY | H8: 20 | I8: 1.5 | J8: Nos
A9: MRG-LPO-00168 | B9: 5 | D9: AL YASIN EQUIPMENT RENTAL LLC | E9: HIRE OF POWER FLOAT | F9: HIRE OF POWER FLOAT | G9: EQUIPMENT, TRANSPORT & MACHINERY | H9: 22 | I9: 60 | J9: Day
A10: MRG-LPO-00413 | B10: 6 | D10: ANCHOR ALLIED FACTORY L.L.C | E10: CP-ASMACO_PUF_4040_(220KG_DRUM) | F10: ASMACO PUF 4040 (220KG DRUM) | G10: PU FOAM | H10: 24 | I10: 2530 | J10: Nos
E11: CP-ASMACO_PUF_MDI_(250KG_DRUM) | F11: ASMACO PUF MDI (250KG DRUM) | G11: PU FOAM | H11: 24 | I11: 2875 | J11: Nos
A12: MRG-LPO-00132-1, MRG-LPO-00211, MRG-LPO-00232, MRG-LPO-00333, MRG-LPO-00351, MRG-LPO-00522, MRG-LPO-00577 | B12: 7 | D12: AWAZEL INTERNATIONAL CO LLC | E12: CP-AWAZEL_FABRIC_(1M*50M) | F12: AWAZEL FABRIC (1M*50M) | G12: FABRIC MESH | H12: 50 | I12: 150 | J12: Nos
E13: CP-AWAZEL_PU_111_ISOCYNATE_(250KG_DRUM) | F13: AWAZEL PU 111 ISOCYNATE (250KG DRUM) | G13: PU FOAM | H13: 28 | I13: 3250 | J13: Nos
E14: CP-AWAZEL_PU_4045_POLYOL_(220KG_DRUM) | F14: AWAZEL PU 4045 POLYOL (220KG DRUM) | G14: PU FOAM | H14: 28 | I14: 2860 | J14: Nos
E15: CP-AWAZEL_PU_4048_POLYOL_(220KG_DRUM) | F15: AWAZEL PU 4048 POLYOL (220KG DRUM) | G15: PU FOAM | H15: 4 | I15: 2640 | J15: Nos
E16: CP-AWAZELBOND_BS_1000_(1M*10M_ROLL) | F16: AWAZELBOND BS 1000 (1M*10M ROLL) | G16: MEMBRANE | H16: 228 | I16: 280 | J16: Nos
E17: CP-MS_60_6MM_PROTECTION_BOARD_(1M*2M_) | F17: MS 60 6MM PROTECTION BOARD (1M*2M ) | G17: PROTECTION BOARD | H17: 150 | I17: 38 | J17: Nos
E18: CP-PY40200L_BSP_10_M_MEMBRANE_SBS_MODIFIED_200G___(1M*10M_ROLL) | F18: PY40200L BSP 10 M MEMBRANE SBS MODIFIED 200G (1M*10M ROLL) | G18: MEMBRANE | H18: 161 | I18: 138 | J18: Nos
E19: CP-PY40L_BSP_10_M_MEMBRANE_SBS_MODIFIED_POLYES_180G___(1M*10M_ROLL) | F19: PY40L BSP 10 M MEMBRANE SBS MODIFIED POLYES 180G (1M*10M ROLL) | G19: MEMBRANE | H19: 69 | I19: 125 | J19: Nos
A20: MRG-LPO-00211, MRG-LPO-00220, MRG-LPO-00351, MRG-LPO-00615 | B20: 8 | D20: AWAZEL INTERNATIONAL CO LLC | E20: CP-AWAZEL_PU_111_ISOCYNATE_(250KG_DRUM) | F20: AWAZEL PU 111 ISOCYNATE (250KG DRUM) | G20: PU FOAM | H20: 4 | I20: 3000 | J20: Nos
E21: CP-AWAZEL_PU_4045_POLYOL_(220KG_DRUM) | F21: AWAZEL PU 4045 POLYOL (220KG DRUM) | G21: PU FOAM | H21: 18 | I21: 2750 | J21: Nos
A22: MRG-LPO-00220, MRG-LPO-00231, MRG-LPO-00615, PUR-ORD-2026-00011 | B22: 9 | D22: AWAZEL INTERNATIONAL CO LLC | E22: CP-AWAZEL_PU_111_ISOCYNATE_(250KG_DRUM) | F22: AWAZEL PU 111 ISOCYNATE (250KG DRUM) | G22: PU FOAM | H22: 18 | I22: 3125 | J22: Nos
E23: CP-MS_60_6MM_PROTECTION_BOARD_(1M*2M_) | F23: MS 60 6MM PROTECTION BOARD (1M*2M ) | G23: PROTECTION BOARD | H23: 750 | I23: 32 | J23: Nos
A24: MRG-LPO-00231, PUR-ORD-2025-00005 | B24: 10 | D24: AWAZEL INTERNATIONAL CO LLC | E24: CP-PY40200L_BSP_10_M_MEMBRANE_SBS_MODIFIED_200G___(1M*10M_ROLL) | F24: PY40200L BSP 10 M MEMBRANE SBS MODIFIED 200G (1M*10M ROLL) | G24: MEMBRANE | H24: 690 | I24: 117 | J24: Nos
A25: MRG-LPO-00008 | B25: 11 | D25: CORROTECH CONSTRUCTION CHEMICALS L.L.C | E25: CP-CORROBOARD_3.2_MM__(1M*2M_) | F25: CORROBOARD 3.2 MM (1M*2M ) | G25: PROTECTION BOARD | H25: 6400 | I25: 17 | J25: Nos
E26: CP-CORROPRIME_SB(200LTR_/DRUM) | F26: CORROPRIME SB(200LTR /DRUM) | G26: BITUMEN | H26: 30 | I26: 750 | J26: Nos
E27: CP-CORROPRUFE_SBS_4180__(1M*10M_ROLL) | F27: CORROPRUFE SBS 4180 (1M*10M ROLL) | G27: MEMBRANE | H27: 3448 | I27: 96 | J27: Nos
A28: MRG-LPO-00118, MRG-LPO-00314 | B28: 12 | D28: CORROTECH CONSTRUCTION CHEMICALS L.L.C | E28: CP-CORROBOARD_3.2_MM__(1M*2M_) | F28: CORROBOARD 3.2 MM (1M*2M ) | G28: PROTECTION BOARD | H28: 200 | I28: 18.9 | J28: Nos
E29: CP-CORROPRUFE_SBS_4180__(1M*10M_ROLL) | F29: CORROPRUFE SBS 4180 (1M*10M ROLL) | G29: MEMBRANE | H29: 506 | I29: 115 | J29: Nos
A30: MRG-LPO-00554-2 | B30: 13 | D30: CORROTECH CONSTRUCTION CHEMICALS L.L.C | E30: CP-CORROPRUFE_SBS_4180__(1M*10M_ROLL) | F30: CORROPRUFE SBS 4180 (1M*10M ROLL) | G30: MEMBRANE | H30: 1012 | I30: 112 | J30: Nos
A31: MRG-LPO-00274-1, MRG-LPO-00602 | B31: 14 | D31: Duproof L.L.C | E31: CP-DUMASTIC_(20KG_PAIL) | F31: DUMASTIC (20KG PAIL) | G31: SEALANT | H31: 32 | I31: 115 | J31: Nos
E32: CP-DUPLAST_P_270_4MM_APP_MEMBRANE_(1M*10M_ROLL) | F32: DUPLAST P 270 4MM APP MEMBRANE (1M*10M ROLL) | G32: MEMBRANE | H32: 46 | I32: 148 | J32: Nos
E33: CP-DUPLAST_P_MEMBRANE_4MM___(1M*10M_ROLL) | F33: DUPLAST P-MEMBRANE 4MM (1M*10M ROLL) | G33: MEMBRANE | H33: 112 | I33: 144 | J33: Nos
E34: CP-DUPRIME_(200LTR_/DRUM) | F34: DUPRIME (200LTR /DRUM) | G34: BITUMEN | H34: 3 | I34: 1300 | J34: Nos
A35: MRG-LPO-00045-1 | B35: 15 | D35: GEOBIT INDUSTRIES L.L.C | E35: CP-BETOFLEX_4P_(1*10_MTR_ROLL) | F35: BETOFLEX 4P (1*10 MTR ROLL) | G35: MEMBRANE | H35: 460 | I35: 110 | J35: Nos
E36: CP-BETOFLEX_PU_ISO_BETOL_(250KG_DRUM) | F36: BETOFLEX PU-ISO BETOL (250KG DRUM) | G36: PU FOAM | H36: 20 | I36: 2150 | J36: Nos
E37: CP-BETOFLEX_PU_PPLY_BETOL_220KG_DRUM) | F37: BETOFLEX PU-PPLY BETOL 220KG DRUM) | G37: PU FOAM | H37: 20 | I37: 1892 | J37: Nos
A38: MRG-LPO-00197 | B38: 16 | D38: GREEN FUSION COMPUTER TRADING LLC | E38: CP-LEASE_CHARGES_FOR_PRINTER_(MONTHLY) | F38: LEASE CHARGES FOR PRINTER (MONTHLY) | G38: EQUIPMENT, TRANSPORT & MACHINERY | H38: 1 | I38: 420 | J38: Nos
A39: MRG-LPO-00197 | B39: 17 | D39: GREEN FUSION COMPUTER TRADING LLC | E39: CP-LEASE_CHARGES_FOR_PRINTER_(MONTHLY) | F39: LEASE CHARGES FOR PRINTER (MONTHLY) | G39: EQUIPMENT, TRANSPORT & MACHINERY | H39: 1 | I39: 350 | J39: Nos
A40: MRG-LPO-00056, MRG-LPO-00545 | B40: 18 | D40: GS ENTERPRISES FZ LLC | E40: CP-NW_120_GSM_PET__WHITE_(3_M_*100_M) | F40: NW 120 GSM PET -WHITE (3 M *100 M) | G40: GEOTEXTILE | H40: 1 | I40: 305 | J40: Nos
...

Sheet Decoding Sheet
A1: PO References | B1: LPO No | C1: Supplier Name | D1: Item Name | E1: Qty | F1: Unit Price | G1: Unit
A2: MRG-LPO-00022 | B2: 1 | C2: AJMAN GAS LLC | D2: PROPANE HIGH PRESSURE REGULATOR WITH GUAGE | E2: 1 | F2: 200 | G2: Nos | I2: {=IFERROR(TOCOL(TEXTSPLIT(_xlfn.TEXTJOIN(CHAR(10),TRUE,'Main Sheet'!L2:L5000),,CHAR(10),TRUE),1),"")}
D3: WATERPRROFING GAS 22 KG | E3: 14 | F3: 110 | G3: CYLINDER
A4: MRG-LPO-00079 | B4: 2 | C4: AJMAN GAS LLC | D4: WATERPRROFING GAS 22 KG | E4: 272 | F4: 126 | G4: CYLINDER
A5: MRG-LPO-00610 | B5: 3 | C5: Al Gurg Fosroc LLC | D5: NITOCOTE CM210 GREY KIT | E5: 150 | F5: 66 | G5: KIT
A6: MRG-LPO-00133 | B6: 4 | C6: Al Nawras Printing Press Services | D6: STICKER 10 X 5 CM | E6: 60 | F6: 0.5 | G6: Nos | H6: {=IFERROR(TRIM(MID(SUBSTITUTE(SUBSTITUTE(SUBSTITUTE(INDEX('Main Sheet'!$L$2:$L$5000,INT((ROWS($H$2:H6)-1)/20)+1),"<br>",CHAR(10)),"<br />",CHAR(10)),CHAR(10),REPT(" ",1000)),MOD(ROWS($H$2:H6)-1,20)*1000+1,1000)),"")}
D7: STICKER 20 X 15 CM | E7: 20 | F7: 1.5 | G7: Nos | H7: {=IFERROR(TRIM(MID(SUBSTITUTE(SUBSTITUTE(INDEX('Main Sheet'!$L$2:$L$5000,INT((ROWS($H$2:H7)-1)/20)+1),"<br>",REPT(" ",1000)),CHAR(10),REPT(" ",1000)),MOD(ROWS($H$2:H7)-1,20)*1000+1,1000)),"")}
A8: MRG-LPO-00168 | B8: 5 | C8: AL YASIN EQUIPMENT RENTAL LLC | D8: POWER FLOAT | E8: 22 | F8: 60 | G8: Nos | H8: {=IFERROR(TRIM(MID(SUBSTITUTE(SUBSTITUTE(INDEX('Main Sheet'!$L$2:$L$5000,INT((ROWS($H$2:H8)-1)/20)+1),"<br>",REPT(" ",1000)),CHAR(10),REPT(" ",1000)),MOD(ROWS($H$2:H8)-1,20)*1000+1,1000)),"")}
A9: MRG-LPO-00413 | B9: 6 | C9: ANCHOR ALLIED FACTORY L.L.C | D9: ASMACO PUF 4040 (220KG) DRUM | E9: 24 | F9: 2530 | G9: Kg | H9: {=IFERROR(TRIM(MID(SUBSTITUTE(SUBSTITUTE(INDEX('Main Sheet'!$L$2:$L$5000,INT((ROWS($H$2:H9)-1)/20)+1),"<br>",REPT(" ",1000)),CHAR(10),REPT(" ",1000)),MOD(ROWS($H$2:H9)-1,20)*1000+1,1000)),"")}
D10: ASMACO PUF MDI (250KG) DRUM | E10: 24 | F10: 2875 | G10: Kg
A11: MRG-LPO-00132-1, MRG-LPO-00211, MRG-LPO-00232, MRG-LPO-00333, MRG-LPO-00351, MRG-LPO-00522, MRG-LPO-00577 | B11: 7 | C11: AWAZEL INTERNATIONAL CO LLC | D11: AWAZEL FABRIC 1M X 50M ROLL | E11: 50 | F11: 150 | G11: ROLL
D12: AWAZEL PU 111 ISOCYNATE (250KG) DRUM | E12: 18 | F12: 3250 | G12: Kg
D13: AWAZEL PU 4045 POLYOL (220KG) DRUM | E13: 28 | F13: 2860 | G13: Kg
D14: AWAZEL PU 4048 POLYOL (220KG) DRUM | E14: 4 | F14: 2640 | G14: Kg
D15: AWAZELBOND BS 1000 | E15: 228 | F15: 280 | G15: ROLL
D16: MS 60 6mm Protection Board (1x2m) | E16: 150 | F16: 38 | G16: SHEET
D17: PY40200L BSP 10 M MEMBRANE SBS MODIFIED 200G | E17: 161 | F17: 138 | G17: M2
D18: PY40L BSP 10 M MEMBRANE SBS MODIFIED POLYES 180G | E18: 69 | F18: 125 | G18: M2
A19: MRG-LPO-00211, MRG-LPO-00220, MRG-LPO-00351, MRG-LPO-00615 | B19: 8 | C19: AWAZEL INTERNATIONAL CO LLC | D19: AWAZEL PU 111 ISOCYNATE (250KG) DRUM | E19: 4 | F19: 3000 | G19: Kg
D20: AWAZEL PU 4045 POLYOL (220KG) DRUM | E20: 18 | F20: 2750 | G20: Kg
A21: MRG-LPO-00220, MRG-LPO-00231, MRG-LPO-00615, PUR-ORD-2026-00011 | B21: 9 | C21: AWAZEL INTERNATIONAL CO LLC | D21: AWAZEL PU 111 ISOCYNATE (250KG) DRUM | E21: 18 | F21: 3125 | G21: Kg
D22: MS 60 6mm Protection Board (1x2m) | E22: 750 | F22: 32 | G22: BD
A23: MRG-LPO-00231, PUR-ORD-2025-00005 | B23: 10 | C23: AWAZEL INTERNATIONAL CO LLC | D23: PY40200L BSP 10 M MEMBRANE SBS MODIFIED 200G | E23: 690 | F23: 117 | G23: M2
A24: MRG-LPO-00008 | B24: 11 | C24: CORROTECH CONSTRUCTION CHEMICALS L.L.C | D24: CORROBOARD 3.2 MM | E24: 6400 | F24: 17 | G24: SHEET
D25: CORROPRIME SB 200LTRS | E25: 30 | F25: 750 | G25: Litre
D26: CORROPRUFE SBS 4180 | E26: 3448 | F26: 96 | G26: ROLL
A27: MRG-LPO-00118, MRG-LPO-00314 | B27: 12 | C27: CORROTECH CONSTRUCTION CHEMICALS L.L.C | D27: CORROBOARD 3.2 MM | E27: 200 | F27: 18.9 | G27: SHEET
D28: CORROPRUFE SBS 4180 | E28: 506 | F28: 115 | G28: ROLL
A29: MRG-LPO-00554-2 | B29: 13 | C29: CORROTECH CONSTRUCTION CHEMICALS L.L.C | D29: CORROPRUFE SBS 4180 | E29: 1012 | F29: 112 | G29: ROLL
A30: MRG-LPO-00274-1, MRG-LPO-00602 | B30: 14 | C30: Duproof L.L.C | D30: DUMASTIC 20 KG | E30: 32 | F30: 115 | G30: PAIL
D31: DUPLAST P 270 4MM APP MEMBRANE 1M X 10 MTR ROLL | E31: 46 | F31: 148 | G31: ROLL
D32: DUPLAST P-MEMBRANE 4MM 1M X 10 MTR ROLL | E32: 112 | F32: 144 | G32: ROLL
D33: DUPRIME 200 LTR DRUM | E33: 3 | F33: 1300 | G33: DRUM
A34: MRG-LPO-00045-1 | B34: 15 | C34: GEOBIT INDUSTRIES L.L.C | D34: BETOFLEX 4P | E34: 460 | F34: 110 | G34: M2
D35: BETOFLEX PU-ISO BETOL 250 KG | E35: 20 | F35: 2150 | G35: Kg
D36: BETOFLEX PU-POLY BETOL 220 KG | E36: 20 | F36: 1892 | G36: Kg
A37: MRG-LPO-00197 | B37: 16 | C37: GREEN FUSION COMPUTER TRADING LLC | D37: PRINTER | E37: 1 | F37: 420 | G37: Months
A38: MRG-LPO-00197 | B38: 17 | C38: GREEN FUSION COMPUTER TRADING LLC | D38: PRINTER | E38: 1 | F38: 350 | G38: Months
A39: MRG-LPO-00056, MRG-LPO-00545 | B39: 18 | C39: GS ENTERPRISES FZ LLC | D39: NW 120 GSM PET -WHITE (3 MTR *100 MTR) | E39: 1 | F39: 305 | G39: M2
D40: NW 250 GSM PET -WHITE (3 MTR *100 MTR) | E40: 50 | F40: 745 | G40: M2
...

Sheet Sheet5
A1: PO References | B1: Supplier Name | C1: Item Name | D1: Qty | F1: Unit Price | G1: Unit
A2: MRG-LPO-00079 | B2: AJMAN GAS LLC | C2: WATERPRROFING GAS 22 KG | D2: 272 | F2: 126 | G2: CYLINDER
A3: MRG-LPO-00022 | B3: AJMAN GAS LLC | C3: WATERPRROFING GAS 22 KG | D3: 14 | F3: 110 | G3: CYLINDER
A4: MRG-LPO-00022 | B4: AJMAN GAS LLC | C4: PROPANE HIGH PRESSURE REGULATOR WITH GUAGE | D4: 1 | F4: 200 | G4: Nos
A5: MRG-LPO-00610 | B5: Al Gurg Fosroc LLC | C5: NITOCOTE CM210 GREY KIT | D5: 150 | F5: 66 | G5: KIT
A6: MRG-LPO-00133 | B6: Al Nawras Printing Press Services | C6: STICKER 20 X 15 CM | D6: 20 | F6: 1.5 | G6: Nos
A7: MRG-LPO-00133 | B7: Al Nawras Printing Press Services | C7: STICKER 10 X 5 CM | D7: 60 | F7: 0.5 | G7: Nos
A8: MRG-LPO-00168 | B8: AL YASIN EQUIPMENT RENTAL LLC | C8: POWER FLOAT | D8: 22 | F8: 60 | G8: Nos
A9: MRG-LPO-00413 | B9: ANCHOR ALLIED FACTORY L.L.C | C9: ASMACO PUF 4040 (220KG) DRUM | D9: 24 | F9: 2530 | G9: Kg
A10: MRG-LPO-00413 | B10: ANCHOR ALLIED FACTORY L.L.C | C10: ASMACO PUF MDI (250KG) DRUM | D10: 24 | F10: 2875 | G10: Kg
A11: MRG-LPO-00220 | B11: AWAZEL INTERNATIONAL CO LLC | C11: AWAZEL PU 4045 POLYOL (220KG) DRUM | D11: 18 | F11: 2750 | G11: Kg
A12: MRG-LPO-00132-1 | B12: AWAZEL INTERNATIONAL CO LLC | C12: AWAZEL PU 4045 POLYOL (220KG) DRUM | D12: 16 | F12: 2860 | G12: Kg
A13: MRG-LPO-00231 | B13: AWAZEL INTERNATIONAL CO LLC | C13: AWAZEL PU 4045 POLYOL (220KG) DRUM | D13: 12 | F13: 2860 | G13: Kg
... A28: MRG-LPO-00333 | B28: AWAZEL INTERNATIONAL CO LLC | C28: AWAZELBOND BS 1000 | D28: 228 | F28: 280 | G28: ROLL
A29: MRG-LPO-00522 | B29: AWAZEL INTERNATIONAL CO LLC | C29: PY40L BSP 10 M MEMBRANE SBS MODIFIED POLYES 180G | D29: 69 | F29: 125 | G29: M2
A30: MRG-LPO-00577 | B30: AWAZEL INTERNATIONAL CO LLC | C30: AWAZEL FABRIC 1M X 50M ROLL | D30: 50 | F30: 150 | G30: ROLL
A31: MRG-LPO-00008 | B31: CORROTECH CONSTRUCTION CHEMICALS L.L.C | C31: CORROPRUFE SBS 4180 | D31: 3448 | F31: 96 | G31: ROLL
A32: MRG-LPO-00554-2 | B32: CORROTECH CONSTRUCTION CHEMICALS L.L.C | C32: CORROPRUFE SBS 4180 | D32: 1012 | F32: 112 | G32: ROLL
A33: MRG-LPO-00314 | B33: CORROTECH CONSTRUCTION CHEMICALS L.L.C | C33: CORROPRUFE SBS 4180 | D33: 506 | F33: 115 | G33: ROLL
A34: MRG-LPO-00008 | B34: CORROTECH CONSTRUCTION CHEMICALS L.L.C | C34: CORROBOARD 3.2 MM | D34: 6400 | F34: 17 | G34: SHEET
A35: MRG-LPO-00118 | B35: CORROTECH CONSTRUCTION CHEMICALS L.L.C | C35: CORROBOARD 3.2 MM | D35: 200 | F35: 18.9 | G35: SHEET
A36: MRG-LPO-00008 | B36: CORROTECH CONSTRUCTION CHEMICALS L.L.C | C36: CORROPRIME SB 200LTRS | D36: 30 | F36: 750 | G36: Litre
A37: MRG-LPO-00274-1 | B37: Duproof L.L.C | C37: DUPRIME 200 LTR DRUM | D37: 3 | F37: 1300 | G37: DRUM
A38: MRG-LPO-00602 | B38: Duproof L.L.C | C38: DUPLAST P 270 4MM APP MEMBRANE 1M X 10 MTR ROLL | D38: 46 | F38: 148 | G38: ROLL
A39: MRG-LPO-00602 | B39: Duproof L.L.C | C39: DUMASTIC 20 KG | D39: 30 | F39: 115 | G39: PAIL
A40: MRG-LPO-00274-1 | B40: Duproof L.L.C | C40: DUMASTIC 20 KG | D40: 2 | F40: 115 | G40: PAIL
... A101: MRG-LPO-00006 | B101: SHERIDAN SPECIALIZED BUILDING PRODUCTS L.L.C | C101: NEONATE MDI (250KG) DRUM | D101: 6 | F101: 2025 | G101: Kg
A102: MRG-LPO-00084-1 | B102: SHERIDAN SPECIALIZED BUILDING PRODUCTS L.L.C | C102: NEONATE MDI (250KG) DRUM | D102: 25 | F102: 2700 | G102: Kg
A103: PUR-ORD-2025-00009 | B103: SHERIDAN SPECIALIZED BUILDING PRODUCTS L.L.C | C103: NEONATE MDI (250KG) DRUM | D103: 14 | F103: 2050 | G103: Kg
A104: MRG-LPO-00596 | B104: SHERIDAN SPECIALIZED BUILDING PRODUCTS L.L.C | C104: NEONATE MDI (250KG) DRUM | D104: 14 | F104: 2950 | G104: Kg
A105: MRG-LPO-00025 | B105: SHERIDAN SPECIALIZED BUILDING PRODUCTS L.L.C | C105: NEONATE MDI (250KG) DRUM | D105: 19 | F105: 2225 | G105: Kg
A106: MRG-LPO-00263 | B106: SHERIDAN SPECIALIZED BUILDING PRODUCTS L.L.C | C106: NEONATE MDI (250KG) DRUM | D106: 40 | F106: 3125 | G106: Kg
A107: MRG-LPO-00044 | B107: SHERIDAN SPECIALIZED BUILDING PRODUCTS L.L.C | C107: NEONATE MDI (250KG) DRUM | D107: 1 | F107: 2600 | G107: Kg
A108: MRG-LPO-00208-1 | B108: SHERIDAN SPECIALIZED BUILDING PRODUCTS L.L.C | C108: NEONATE MDI (250KG) DRUM | D108: 13 | F108: 3125 | G108: Kg
A109: MRG-LPO-00006 | B109: SHERIDAN SPECIALIZED BUILDING PRODUCTS L.L.C | C109: NEOPOL SRS 45 (220KG) DRUM | D109: 6 | F109: 1782 | G109: Kg
A110: MRG-LPO-00084-1 | B110: SHERIDAN SPECIALIZED BUILDING PRODUCTS L.L.C | C110: NEOPOL SRS 45 (220KG) DRUM | D110: 25 | F110: 2376 | G110: Kg
A111: PUR-ORD-2025-00009 | B111: SHERIDAN SPECIALIZED BUILDING PRODUCTS L.L.C | C111: NEOPOL SRS 45 (220KG) DRUM | D111: 14 | F111: 1804 | G111: Kg
A112: MRG-LPO-00596 | B112: SHERIDAN SPECIALIZED BUILDING PRODUCTS L.L.C | C112: NEOPOL SRS 45 (220KG) DRUM | D112: 14 | F112: 2596 | G112: Kg
A113: MRG-LPO-00596 | B113: SHERIDAN SPECIALIZED BUILDING PRODUCTS L.L.C | C113: NEOPOL SRS 45 (220KG) DRUM | D113: 5 | F113: 2596 | G113: Kg
... A147: MRG-LPO-00016 | B147: SIKA UAE LLC | C147: SIKA SHIELD P26 MG SA 4MM ROLL 1MX10M | D147: 1777 | F147: 115 | G147: M2
...

Sheet Main Sheet
A1: PO References | B1: Supplier Name | C1: Old Name | D1: Presence check | E1: Validate | F1: Item Code | G1: Item Name | H1: Test Qty | I1: Qty | J1: Difference | K1: Unit Fetch | L1: Item Details | M1: Project/Warehouse
A2: MRG-LPO-00022, MRG-LPO-00079 | B2: AJMAN GAS LLC | C2: WATERPRROFING GAS 22 KG | D2: WATERPRROFING GAS 22 KG | E2: Match | F2: CP-WATERPRROFING_GAS_(22KG) | G2: WATERPRROFING GAS (22KG) | H2: 286 | I2: 286 | J2: 0 | K2: Nos | L2: {=IFERROR( _xlfn.TEXTJOIN(CHAR(10),TRUE, _xlfn._xlws.FILTER( "Name: "&'Master Data'!$J$2:$J$10000& " Price: "&'Master Data'!$L$2:$L$10000& " Qty: "&('Master Data'!$K$2:$K$10000-'Master Data'!$Q$2:$Q$10000)& " Unit: "&'Master Data'!$N$2:$N$10000& " Supplier Reference: "&'Master Data'!$B$2:$B$10000& " PO Reference: "&'Master Data'!$A$2:$A$10000, ('Master Data'!$J$2:$J$10000=D2)* (('Master Data'!$K$2:$K$10000-'Master Data'!$Q$2:$Q$10000)<>0) ) ), "Not Found")} -> Name: WATERPRROFING GAS 22 KG Price: 110 Qty: 14 Unit: CYLINDER Supplier Reference: AJMAN GAS LLC PO Reference: MRG-LPO-00022 Name: WATERPRROFING GAS 22 KG Price: 126 Qty: 272 Unit: CYLINDER Supplier Reference: AJMAN GAS LLC PO Reference: MRG-LPO-00079 | M2: Stores - MRG
B3: AJMAN GAS LLC | C3: PROPANE HIGH PRESSURE REGULATOR WITH GUAGE | D3: PROPANE HIGH PRESSURE REGULATOR WITH GUAGE | E3: Match | F3: PROPANE HIGH PRESSURE REGULATOR WITH GUAGE | G3: PROPANE HIGH PRESSURE REGULATOR WITH GUAGE | H3: 1 | I3: 1 | J3: 0 | K3: Nos | L3: {=IFERROR( _xlfn.TEXTJOIN(CHAR(10),TRUE, _xlfn._xlws.FILTER( "Name: "&'Master Data'!$J$2:$J$10000& " Price: "&'Master Data'!$L$2:$L$10000& " Qty: "&('Master Data'!$K$2:$K$10000-'Master Data'!$Q$2:$Q$10000)& " Unit: "&'Master Data'!$N$2:$N$10000& " Supplier Reference: "&'Master Data'!$B$2:$B$10000& " PO Reference: "&'Master Data'!$A$2:$A$10000, ('Master Data'!$J$2:$J$10000=D3)* (('Master Data'!$K$2:$K$10000-'Master Data'!$Q$2:$Q$10000)<>0) ) ), "Not Found")} -> Name: PROPANE HIGH PRESSURE REGULATOR WITH GUAGE Price: 200 Qty: 1 Unit: Nos Supplier Reference: MR MD For Project Management Services EST PO Reference: PUR-ORD-2026-00049 | M3: Stores - MRG
A4: MRG-LPO-00610 | B4: Al Gurg Fosroc LLC | C4: NITOCOTE CM210 GREY KIT | D4: NITOCOTE CM210 GREY KIT | E4: Match | F4: CP-NITOCOTE_CM210_GREY_(_PART_A_15KG+_PART_B_5KG) | G4: NITOCOTE CM210 GREY ( PART A 15KG+ PART B 5KG) | H4: 150 | I4: 150 | J4: 0 | K4: Nos | L4: {=IFERROR( _xlfn.TEXTJOIN(CHAR(10),TRUE, _xlfn._xlws.FILTER( "Name: "&'Master Data'!$J$2:$J$10000& " Price: "&'Master Data'!$L$2:$L$10000& " Qty: "&('Master Data'!$K$2:$K$10000-'Master Data'!$Q$2:$Q$10000)& " Unit: "&'Master Data'!$N$2:$N$10000& " Supplier Reference: "&'Master Data'!$B$2:$B$10000& " PO Reference: "&'Master Data'!$A$2:$A$10000, ('Master Data'!$J$2:$J$10000=D4)* (('Master Data'!$K$2:$K$10000-'Master Data'!$Q$2:$Q$10000)<>0) ) ), "Not Found")} -> Name: NITOCOTE CM210 GREY KIT Price: 66 Qty: 150 Unit: KIT Supplier Reference: Al Gurg Fosroc LLC PO Reference: MRG-LPO-00610 | M4: Stores - MRG
A5: MRG-LPO-00133 | B5: Al Nawras Printing Press Services | C5: STICKER 20 X 15 CM | D5: STICKER 20 X 15 CM | E5: Match | F5: STICKER 20 X 15 CM | G5: STICKER 20 X 15 CM | H5: 20 | I5: 20 | J5: 0 | K5: Nos | L5: {=IFERROR( _xlfn.TEXTJOIN(CHAR(10),TRUE, _xlfn._xlws.FILTER( "Name: "&'Master Data'!$J$2:$J$10000& " Price: "&'Master Data'!$L$2:$L$10000& " Qty: "&('Master Data'!$K$2:$K$10000-'Master Data'!$Q$2:$Q$10000)& " Unit: "&'Master Data'!$N$2:$N$10000& " Supplier Reference: "&'Master Data'!$B$2:$B$10000& " PO Reference: "&'Master Data'!$A$2:$A$10000, ('Master Data'!$J$2:$J$10000=D5)* (('Master Data'!$K$2:$K$10000-'Master Data'!$Q$2:$Q$10000)<>0) ) ), "Not Found")} -> Name: STICKER 20 X 15 CM Price: 1.5 Qty: 20 Unit: Nos Supplier Reference: MR MD For Project Management Services EST PO Reference: PUR-ORD-2026-00049 | M5: Stores - MRG
B6: Al Nawras Printing Press Services | C6: STICKER 10 X 5 CM | D6: STICKER 10 X 5 CM | E6: Match | F6: CP-STICKER_10_X_5_CM | G6: STICKER 10 X 5 CM | H6: 60 | I6: 60 | J6: 0 | K6: Nos | L6: {=IFERROR( _xlfn.TEXTJOIN(CHAR(10),TRUE, _xlfn._xlws.FILTER( "Name: "&'Master Data'!$J$2:$J$10000& " Price: "&'Master Data'!$L$2:$L$10000& " Qty: "&('Master Data'!$K$2:$K$10000-'Master Data'!$Q$2:$Q$10000)& " Unit: "&'Master Data'!$N$2:$N$10000& " Supplier Reference: "&'Master Data'!$B$2:$B$10000& " PO Reference: "&'Master Data'!$A$2:$A$10000, ('Master Data'!$J$2:$J$10000=D6)* (('Master Data'!$K$2:$K$10000-'Master Data'!$Q$2:$Q$10000)<>0) ) ), "Not Found")} -> Name: STICKER 10 X 5 CM Price: 0.5 Qty: 60 Unit: Nos Supplier Reference: MR MD For Project Management Services EST PO Reference: PUR-ORD-2026-00049 | M6: Stores - MRG
A7: MRG-LPO-00168 | B7: AL YASIN EQUIPMENT RENTAL LLC | C7: POWER FLOAT | D7: POWER FLOAT | E7: Match | F7: HIRE OF POWER FLOAT | G7: HIRE OF POWER FLOAT | H7: 22 | I7: 22 | J7: 0 | K7: Day | L7: {=IFERROR( _xlfn.TEXTJOIN(CHAR(10),TRUE, _xlfn._xlws.FILTER( "Name: "&'Master Data'!$J$2:$J$10000& " Price: "&'Master Data'!$L$2:$L$10000& " Qty: "&('Master Data'!$K$2:$K$10000-'Master Data'!$Q$2:$Q$10000)& " Unit: "&'Master Data'!$N$2:$N$10000& " Supplier Reference: "&'Master Data'!$B$2:$B$10000& " PO Reference: "&'Master Data'!$A$2:$A$10000, ('Master Data'!$J$2:$J$10000=D7)* (('Master Data'!$K$2:$K$10000-'Master Data'!$Q$2:$Q$10000)<>0) ) ), "Not Found")} -> Name: POWER FLOAT Price: 60 Qty: 22 Unit: Nos Supplier Reference: MR MD For Project Management Services EST PO Reference: PUR-ORD-2026-00049 | M7: Stores - MRG
A8: MRG-LPO-00413 | B8: ANCHOR ALLIED FACTORY L.L.C | C8: ASMACO PUF 4040 (220KG) DRUM | D8: ASMACO PUF 4040 (220KG) DRUM | E8: Match | F8: CP-ASMACO_PUF_4040_(220KG_DRUM) | G8: ASMACO PUF 4040 (220KG DRUM) | H8: 24 | I8: 24 | J8: 0 | K8: Nos | L8: {=IFERROR( _xlfn.TEXTJOIN(CHAR(10),TRUE, _xlfn._xlws.FILTER( "Name: "&'Master Data'!$J$2:$J$10000& " Price: "&'Master Data'!$L$2:$L$10000& " Qty: "&('Master Data'!$K$2:$K$10000-'Master Data'!$Q$2:$Q$10000)& " Unit: "&'Master Data'!$N$2:$N$10000& " Supplier Reference: "&'Master Data'!$B$2:$B$10000& " PO Reference: "&'Master Data'!$A$2:$A$10000, ('Master Data'!$J$2:$J$10000=D8)* (('Master Data'!$K$2:$K$10000-'Master Data'!$Q$2:$Q$10000)<>0) ) ), "Not Found")} -> Name: ASMACO PUF 4040 (220KG) DRUM Price: 2530 Qty: 24 Unit: Kg Supplier Reference: ANCHOR ALLIED FACTORY L.L.C PO Reference: MRG-LPO-00413 | M8: Stores - MRG
B9: ANCHOR ALLIED FACTORY L.L.C | C9: ASMACO PUF MDI (250KG) DRUM | D9: ASMACO PUF MDI (250KG) DRUM | E9: Match | F9: CP-ASMACO_PUF_MDI_(250KG_DRUM) | G9: ASMACO PUF MDI (250KG DRUM) | H9: 24 | I9: 24 | J9: 0 | K9: Nos | L9: {=IFERROR( _xlfn.TEXTJOIN(CHAR(10),TRUE, _xlfn._xlws.FILTER( "Name: "&'Master Data'!$J$2:$J$10000& " Price: "&'Master Data'!$L$2:$L$10000& " Qty: "&('Master Data'!$K$2:$K$10000-'Master Data'!$Q$2:$Q$10000)& " Unit: "&'Master Data'!$N$2:$N$10000& " Supplier Reference: "&'Master Data'!$B$2:$B$10000& " PO Reference: "&'Master Data'!$A$2:$A$10000, ('Master Data'!$J$2:$J$10000=D9)* (('Master Data'!$K$2:$K$10000-'Master Data'!$Q$2:$Q$10000)<>0) ) ), "Not Found")} -> Name: ASMACO PUF MDI (250KG) DRUM Price: 2875 Qty: 24 Unit: Kg Supplier Reference: MR MD For Project Management Services EST PO Reference: PUR-ORD-2026-00049 | M9: Stores - MRG
A10: MRG-LPO-00132-1, MRG-LPO-00211, MRG-LPO-00220, MRG-LPO-00231, MRG-LPO-00232, MRG-LPO-00333, MRG-LPO-00351, MRG-LPO-00522, MRG-LPO-00577, MRG-LPO-00600, MRG-LPO-00615, PUR-ORD-2026-00011 | B10: AWAZEL INTERNATIONAL CO LLC | C10: AWAZEL PU 4045 POLYOL (220KG) DRUM | D10: AWAZEL PU 4045 POLYOL (220KG) DRUM | E10: Match | F10: CP-AWAZEL_PU_4045_POLYOL_(220KG_DRUM) | G10: AWAZEL PU 4045 POLYOL (220KG DRUM) | H10: 46 | I10: 46 | J10: 0 | K10: Nos | L10: {=IFERROR( _xlfn.TEXTJOIN(CHAR(10),TRUE, _xlfn._xlws.FILTER( "Name: "&'Master Data'!$J$2:$J$10000& " Price: "&'Master Data'!$L$2:$L$10000& " Qty: "&('Master Data'!$K$2:$K$10000-'Master Data'!$Q$2:$Q$10000)& " Unit: "&'Master Data'!$N$2:$N$10000& " Supplier Reference: "&'Master Data'!$B$2:$B$10000& " PO Reference: "&'Master Data'!$A$2:$A$10000, ('Master Data'!$J$2:$J$10000=D10)* (('Master Data'!$K$2:$K$10000-'Master Data'!$Q$2:$Q$10000)<>0) ) ), "Not Found")} -> Name: AWAZEL PU 4045 POLYOL (220KG) DRUM Price: 2750 Qty: 18 Unit: Kg Supplier Reference: AWAZEL INTERNATIONAL CO LLC PO Reference: MRG-LPO-00220 Name: AWAZEL PU 4045 POLYOL (220KG) DRUM Price: 2860 Qty: 16 Unit: Kg Supplier Reference: AWAZEL INTERNATIONAL CO LLC PO Reference: MRG-LPO-00132-1 Name: AWAZEL PU 4045 POLYOL (220KG) DRUM Price: 2860 Qty: 12 Unit: Kg Supplier Reference: AWAZEL INTERNATIONAL CO LLC PO Reference: MRG-LPO-00231 | M10: Stores - MRG
B11: AWAZEL INTERNATIONAL CO LLC | C11: AWAZEL PU 111 ISOCYNATE (250KG) DRUM | D11: AWAZEL PU 111 ISOCYNATE (250KG) DRUM | E11: Match | F11: CP-AWAZEL_PU_111_ISOCYNATE_(250KG_DRUM) | G11: AWAZEL PU 111 ISOCYNATE (250KG DRUM) | H11: 50 | I11: 50 | J11: 0 | K11: Nos | L11: {=IFERROR( _xlfn.TEXTJOIN(CHAR(10),TRUE, _xlfn._xlws.FILTER( "Name: "&'Master Data'!$J$2:$J$10000& " Price: "&'Master Data'!$L$2:$L$10000& " Qty: "&('Master Data'!$K$2:$K$10000-'Master Data'!$Q$2:$Q$10000)& " Unit: "&'Master Data'!$N$2:$N$10000& " Supplier Reference: "&'Master Data'!$B$2:$B$10000& " PO Reference: "&'Master Data'!$A$2:$A$10000, ('Master Data'!$J$2:$J$10000=D11)* (('Master Data'!$K$2:$K$10000-'Master Data'!$Q$2:$Q$10000)<>0) ) ), "Not Found")} -> Name: AWAZEL PU 111 ISOCYNATE (250KG) DRUM Price: 3125 Qty: 18 Unit: Kg Supplier Reference: MR MD For Project Management Services EST PO Reference: PUR-ORD-2026-00049 Name: AWAZEL PU 111 ISOCYNATE (250KG) DRUM Price: 3250 Qty: 16 Unit: Kg Supplier Reference: MR MD For Project Management Services EST PO Reference: PUR-ORD-2026-00049 Name: AWAZEL PU 111 ISOCYNATE (250KG) DRUM Price: 3250 Qty: 12 Unit: Kg Supplier Reference: MR MD For Project Management Services EST PO Reference: PUR-ORD-2026-00049 Name: AWAZEL PU 111 ISOCYNATE (250KG) DRUM Price: 3000 Qty: 4 Unit: Kg Supplier Reference: MR MD For Project Management Services EST PO Reference: PUR-ORD-2026-00049 | M11: Stores - MRG
B12: AWAZEL INTERNATIONAL CO LLC | C12: AWAZEL PU 4048 POLYOL (220KG) DRUM | D12: AWAZEL PU 4048 POLYOL (220KG) DRUM | E12: Match | F12: CP-AWAZEL_PU_4048_POLYOL_(220KG_DRUM) | G12: AWAZEL PU 4048 POLYOL (220KG DRUM) | H12: 4 | I12: 4 | J12: 0 | K12: Nos | L12: {=IFERROR( _xlfn.TEXTJOIN(CHAR(10),TRUE, _xlfn._xlws.FILTER( "Name: "&'Master Data'!$J$2:$J$10000& " Price: "&'Master Data'!$L$2:$L$10000& " Qty: "&('Master Data'!$K$2:$K$10000-'Master Data'!$Q$2:$Q$10000)& " Unit: "&'Master Data'!$N$2:$N$10000& " Supplier Reference: "&'Master Data'!$B$2:$B$10000& " PO Reference: "&'Master Data'!$A$2:$A$10000, ('Master Data'!$J$2:$J$10000=D12)* (('Master Data'!$K$2:$K$10000-'Master Data'!$Q$2:$Q$10000)<>0) ) ), "Not Found")} -> Name: AWAZEL PU 4048 POLYOL (220KG) DRUM Price: 2640 Qty: 4 Unit: Kg Supplier Reference: AWAZEL INTERNATIONAL CO LLC PO Reference: MRG-LPO-00211 | M12: Stores - MRG
B13: AWAZEL INTERNATIONAL CO LLC | C13: PY40200L BSP 10 M MEMBRANE SBS MODIFIED 200G | D13: PY40200L BSP 10 M MEMBRANE SBS MODIFIED 200G | E13: Match | F13: CP-PY40200L_BSP_10_M_MEMBRANE_SBS_MODIFIED_200G___(1M*10M_ROLL) | G13: PY40200L BSP 10 M MEMBRANE SBS MODIFIED 200G (1M*10M ROLL) | H13: 851 | I13: 345 | J13: -506 | K13: Nos | L13: {=IFERROR( _xlfn.TEXTJOIN(CHAR(10),TRUE, _xlfn._xlws.FILTER( "Name: "&'Master Data'!$J$2:$J$10000& " Price: "&'Master Data'!$L$2:$L$10000& " Qty: "&('Master Data'!$K$2:$K$10000-'Master Data'!$Q$2:$Q$10000)& " Unit: "&'Master Data'!$N$2:$N$10000& " Supplier Reference: "&'Master Data'!$B$2:$B$10000& " PO Reference: "&'Master Data'!$A$2:$A$10000, ('Master Data'!$J$2:$J$10000=D13)* (('Master Data'!$K$2:$K$10000-'Master Data'!$Q$2:$Q$10000)<>0) ) ), "Not Found")} -> Name: PY40200L BSP 10 M MEMBRANE SBS MODIFIED 200G Price: 117 Qty: 276 Unit: M2 Supplier Reference: AWAZEL INTERNATIONAL CO LLC PO Reference: PUR-ORD-2025-00005 Name: PY40200L BSP 10 M MEMBRANE SBS MODIFIED 200G Price: 117 Qty: 230 Unit: M2 Supplier Reference: AWAZEL INTERNATIONAL CO LLC PO Reference: PUR-ORD-2025-00008 Name: PY40200L BSP 10 M MEMBRANE SBS MODIFIED 200G Price: 117 Qty: 184 Unit: M2 Supplier Reference: AWAZEL INTERNATIONAL CO LLC PO Reference: PUR-ORD-2026-00011 Name: PY40200L BSP 10 M MEMBRANE SBS MODIFIED 200G Price: 138 Qty: 115 Unit: M2 Supplier Reference: AWAZEL INTERNATIONAL CO LLC PO Reference: MRG-LPO-00351 Name: PY40200L BSP 10 M MEMBRANE SBS MODIFIED 200G Price: 138 Qty: 30 Unit: M2 Supplier Reference: AWAZEL INTERNATIONAL CO LLC PO Reference: MRG-LPO-00615 Name: PY40200L BSP 10 M MEMBRANE SBS MODIFIED 200G Price: 138 Qty: 16 Unit: M2 Supplier Reference: MR MD For Project Management Services EST PO Reference: PUR-ORD-2026-00049 | M13: Stores - MRG
B14: AWAZEL INTERNATIONAL CO LLC | C14: MS 60 6mm Protection Board (1x2m) | D14: MS 60 6mm Protection Board (1x2m) | E14: Match | F14: CP-MS_60_6MM_PROTECTION_BOARD_(1M*2M_) | G14: MS 60 6MM PROTECTION BOARD (1M*2M ) | H14: 900 | I14: 900 | J14: 0 | K14: Nos | L14: {=IFERROR( _xlfn.TEXTJOIN(CHAR(10),TRUE, _xlfn._xlws.FILTER( "Name: "&'Master Data'!$J$2:$J$10000& " Price: "&'Master Data'!$L$2:$L$10000& " Qty: "&('Master Data'!$K$2:$K$10000-'Master Data'!$Q$2:$Q$10000)& " Unit: "&'Master Data'!$N$2:$N$10000& " Supplier Reference: "&'Master Data'!$B$2:$B$10000& " PO Reference: "&'Master Data'!$A$2:$A$10000, ('Master Data'!$J$2:$J$10000=D14)* (('Master Data'!$K$2:$K$10000-'Master Data'!$Q$2:$Q$10000)<>0) ) ), "Not Found")} -> Name: MS 60 6mm Protection Board (1x2m) Price: 38 Qty: 50 Unit: BD Supplier Reference: MR MD For Project Management Services EST PO Reference: PUR-ORD-2026-00049 Name: MS 60 6mm Protection Board (1x2m) Price: 32 Qty: 750 Unit: BD Supplier Reference: MR MD For Project Management Services EST PO Reference: PUR-ORD-2026-00049 Name: MS 60 6mm Protection Board (1x2m) Price: 38 Qty: 100 Unit: SHEET Supplier Reference: MR MD For Project Management Services EST PO Reference: PUR-ORD-2026-00049 | M14: Stores - MRG
B15: AWAZEL INTERNATIONAL CO LLC | C15: AWAZELBOND BS 1000 | D15: AWAZELBOND BS 1000 | E15: Match | F15: CP-AWAZELBOND_BS_1000_(1M*10M_ROLL) | G15: AWAZELBOND BS 1000 (1M*10M ROLL) | H15: 228 | I15: 228 | J15: 0 | K15: Nos | L15: {=IFERROR( _xlfn.TEXTJOIN(CHAR(10),TRUE, _xlfn._xlws.FILTER( "Name: "&'Master Data'!$J$2:$J$10000& " Price: "&'Master Data'!$L$2:$L$10000& " Qty: "&('Master Data'!$K$2:$K$10000-'Master Data'!$Q$2:$Q$10000)& " Unit: "&'Master Data'!$N$2:$N$10000& " Supplier Reference: "&'Master Data'!$B$2:$B$10000& " PO Reference: "&'Master Data'!$A$2:$A$10000, ('Master Data'!$J$2:$J$10000=D15)* (('Master Data'!$K$2:$K$10000-'Master Data'!$Q$2:$Q$10000)<>0) ) ), "Not Found")} -> Name: AWAZELBOND BS 1000 Price: 280 Qty: 228 Unit: ROLL Supplier Reference: AWAZEL INTERNATIONAL CO LLC PO Reference: MRG-LPO-00333 | M15: Stores - MRG
B16: AWAZEL INTERNATIONAL CO LLC | C16: PY40L BSP 10 M MEMBRANE SBS MODIFIED POLYES 180G | D16: PY40L BSP 10 M MEMBRANE SBS MODIFIED POLYES 180G | E16: Match | F16: CP-PY40L_BSP_10_M_MEMBRANE_SBS_MODIFIED_POLYES_180G___(1M*10M_ROLL) | G16: PY40L BSP 10 M MEMBRANE SBS MODIFIED POLYES 180G (1M*10M ROLL) | H16: 69 | I16: 69 | J16: 0 | K16: Nos | L16: {=IFERROR( _xlfn.TEXTJOIN(CHAR(10),TRUE, _xlfn._xlws.FILTER( "Name: "&'Master Data'!$J$2:$J$10000& " Price: "&'Master Data'!$L$2:$L$10000& " Qty: "&('Master Data'!$K$2:$K$10000-'Master Data'!$Q$2:$Q$10000)& " Unit: "&'Master Data'!$N$2:$N$10000& " Supplier Reference: "&'Master Data'!$B$2:$B$10000& " PO Reference: "&'Master Data'!$A$2:$A$10000, ('Master Data'!$J$2:$J$10000=D16)* (('Master Data'!$K$2:$K$10000-'Master Data'!$Q$2:$Q$10000)<>0) ) ), "Not Found")} -> Name: PY40L BSP 10 M MEMBRANE SBS MODIFIED POLYES 180G Price: 125 Qty: 69 Unit: M2 Supplier Reference: AWAZEL INTERNATIONAL CO LLC PO Reference: MRG-LPO-00522 | M16: Stores - MRG
B17: AWAZEL INTERNATIONAL CO LLC | C17: AWAZEL FABRIC 1M X 50M ROLL | D17: AWAZEL FABRIC 1M X 50M ROLL | E17: Match | F17: CP-AWAZEL_FABRIC_(1M*50M) | G17: AWAZEL FABRIC (1M*50M) | H17: 50 | I17: 50 | J17: 0 | K17: Nos | L17: {=IFERROR( _xlfn.TEXTJOIN(CHAR(10),TRUE, _xlfn._xlws.FILTER( "Name: "&'Master Data'!$J$2:$J$10000& " Price: "&'Master Data'!$L$2:$L$10000& " Qty: "&('Master Data'!$K$2:$K$10000-'Master Data'!$Q$2:$Q$10000)& " Unit: "&'Master Data'!$N$2:$N$10000& " Supplier Reference: "&'Master Data'!$B$2:$B$10000& " PO Reference: "&'Master Data'!$A$2:$A$10000, ('Master Data'!$J$2:$J$10000=D17)* (('Master Data'!$K$2:$K$10000-'Master Data'!$Q$2:$Q$10000)<>0) ) ), "Not Found")} -> Name: AWAZEL FABRIC 1M X 50M ROLL Price: 150 Qty: 50 Unit: ROLL Supplier Reference: AWAZEL INTERNATIONAL CO LLC PO Reference: MRG-LPO-00577 | M17: Stores - MRG
A18: MRG-LPO-00008, MRG-LPO-00118, MRG-LPO-00314, MRG-LPO-00554-2 | B18: CORROTECH CONSTRUCTION CHEMICALS L.L.C | C18: CORROPRUFE SBS 4180 | D18: CORROPRUFE SBS 4180 | E18: Match | F18: CP-CORROPRUFE_SBS_4180__(1M*10M_ROLL) | G18: CORROPRUFE SBS 4180 (1M*10M ROLL) | H18: 4966 | I18: 496.6 | J18: -4469.4 | K18: Nos | L18: {=IFERROR( _xlfn.TEXTJOIN(CHAR(10),TRUE, _xlfn._xlws.FILTER( "Name: "&'Master Data'!$J$2:$J$10000& " Price: "&'Master Data'!$L$2:$L$10000& " Qty: "&('Master Data'!$K$2:$K$10000-'Master Data'!$Q$2:$Q$10000)& " Unit: "&'Master Data'!$N$2:$N$10000& " Supplier Reference: "&'Master Data'!$B$2:$B$10000& " PO Reference: "&'Master Data'!$A$2:$A$10000, ('Master Data'!$J$2:$J$10000=D18)* (('Master Data'!$K$2:$K$10000-'Master Data'!$Q$2:$Q$10000)<>0) ) ), "Not Found")} -> Name: CORROPRUFE SBS 4180 Price: 96 Qty: 3448 Unit: ROLL Supplier Reference: CORROTECH CONSTRUCTION CHEMICALS L.L.C PO Reference: MRG-LPO-00008 Name: CORROPRUFE SBS 4180 Price: 115 Qty: 506 Unit: ROLL Supplier Reference: CORROTECH CONSTRUCTION CHEMICALS L.L.C PO Reference: MRG-LPO-00314 Name: CORROPRUFE SBS 4180 Price: 112 Qty: 1012 Unit: ROLL Supplier Reference: CORROTECH CONSTRUCTION CHEMICALS L.L.C PO Reference: MRG-LPO-00554-2 | M18: Stores - MRG
B19: CORROTECH CONSTRUCTION CHEMICALS L.L.C | C19: CORROBOARD 3.2 MM | D19: CORROBOARD 3.2 MM | E19: Match | F19: CP-CORROBOARD_3.2_MM__(1M*2M_) | G19: CORROBOARD 3.2 MM (1M*2M ) | H19: 6600 | I19: 6600 | J19: 0 | K19: Nos | L19: {=IFERROR( _xlfn.TEXTJOIN(CHAR(10),TRUE, _xlfn._xlws.FILTER( "Name: "&'Master Data'!$J$2:$J$10000& " Price: "&'Master Data'!$L$2:$L$10000& " Qty: "&('Master Data'!$K$2:$K$10000-'Master Data'!$Q$2:$Q$10000)& " Unit: "&'Master Data'!$N$2:$N$10000& " Supplier Reference: "&'Master Data'!$B$2:$B$10000& " PO Reference: "&'Master Data'!$A$2:$A$10000, ('Master Data'!$J$2:$J$10000=D19)* (('Master Data'!$K$2:$K$10000-'Master Data'!$Q$2:$Q$10000)<>0) ) ), "Not Found")} -> Name: CORROBOARD 3.2 MM Price: 18.9 Qty: 200 Unit: SHEET Supplier Reference: CORROTECH CONSTRUCTION CHEMICALS L.L.C PO Reference: MRG-LPO-00118 Name: CORROBOARD 3.2 MM Price: 17 Qty: 6400 Unit: SHEET Supplier Reference: MR MD For Project Management Services EST PO Reference: PUR-ORD-2026-00049 | M19: Stores - MRG | N19: D
B20: CORROTECH CONSTRUCTION CHEMICALS L.L.C | C20: CORROPRIME SB 200LTRS | D20: CORROPRIME SB 200LTRS | E20: Match | F20: CP-CORROPRIME_SB(200LTR_/DRUM) | G20: CORROPRIME SB(200LTR /DRUM) | H20: 30 | I20: 30 | J20: 0 | K20: Nos | L20: {=IFERROR( _xlfn.TEXTJOIN(CHAR(10),TRUE, _xlfn._xlws.FILTER( "Name: "&'Master Data'!$J$2:$J$10000& " Price: "&'Master Data'!$L$2:$L$10000& " Qty: "&('Master Data'!$K$2:$K$10000-'Master Data'!$Q$2:$Q$10000)& " Unit: "&'Master Data'!$N$2:$N$10000& " Supplier Reference: "&'Master Data'!$B$2:$B$10000& " PO Reference: "&'Master Data'!$A$2:$A$10000, ('Master Data'!$J$2:$J$10000=D20)* (('Master Data'!$K$2:$K$10000-'Master Data'!$Q$2:$Q$10000)<>0) ) ), "Not Found")} -> Name: CORROPRIME SB 200LTRS Price: 750 Qty: 30 Unit: Litre Supplier Reference: MR MD For Project Management Services EST PO Reference: PUR-ORD-2026-00049 | M20: Stores - MRG
A21: MRG-LPO-00274-1, MRG-LPO-00602 | B21: Duproof L.L.C | C21: DUPRIME 200 LTR DRUM | D21: DUPRIME 200 LTR DRUM | E21: Match | F21: CP-DUPRIME_(200LTR_/DRUM) | G21: DUPRIME (200LTR /DRUM) | H21: 3 | I21: 3 | J21: 0 | K21: Nos | L21: {=IFERROR( _xlfn.TEXTJOIN(CHAR(10),TRUE, _xlfn._xlws.FILTER( "Name: "&'Master Data'!$J$2:$J$10000& " Price: "&'Master Data'!$L$2:$L$10000& " Qty: "&('Master Data'!$K$2:$K$10000-'Master Data'!$Q$2:$Q$10000)& " Unit: "&'Master Data'!$N$2:$N$10000& " Supplier Reference: "&'Master Data'!$B$2:$B$10000& " PO Reference: "&'Master Data'!$A$2:$A$10000, ('Master Data'!$J$2:$J$10000=D21)* (('Master Data'!$K$2:$K$10000-'Master Data'!$Q$2:$Q$10000)<>0) ) ), "Not Found")} -> Name: DUPRIME 200 LTR DRUM Price: 1300 Qty: 3 Unit: DRUM Supplier Reference: Duproof L.L.C PO Reference: MRG-LPO-00274-1 | M21: Stores - MRG
B22: Duproof L.L.C | C22: DUPLAST P 270 4MM APP MEMBRANE 1M X 10 MTR ROLL | D22: DUPLAST P 270 4MM APP MEMBRANE 1M X 10 MTR ROLL | E22: Match | F22: CP-DUPLAST_P_270_4MM_APP_MEMBRANE_(1M*10M_ROLL) | G22: DUPLAST P 270 4MM APP MEMBRANE (1M*10M ROLL) | H22: 46 | I22: 46 | J22: 0 | K22: Nos | L22: {=IFERROR( _xlfn.TEXTJOIN(CHAR(10),TRUE, _xlfn._xlws.FILTER( "Name: "&'Master Data'!$J$2:$J$10000& " Price: "&'Master Data'!$L$2:$L$10000& " Qty: "&('Master Data'!$K$2:$K$10000-'Master Data'!$Q$2:$Q$10000)& " Unit: "&'Master Data'!$N$2:$N$10000& " Supplier Reference: "&'Master Data'!$B$2:$B$10000& " PO Reference: "&'Master Data'!$A$2:$A$10000, ('Master Data'!$J$2:$J$10000=D22)* (('Master Data'!$K$2:$K$10000-'Master Data'!$Q$2:$Q$10000)<>0) ) ), "Not Found")} -> Name: DUPLAST P 270 4MM APP MEMBRANE 1M X 10 MTR ROLL Price: 148 Qty: 46 Unit: ROLL Supplier Reference: Duproof L.L.C PO Reference: MRG-LPO-00602 | M22: Stores - MRG
B23: Duproof L.L.C | C23: DUMASTIC 20 KG | D23: DUMASTIC 20 KG | E23: Match | F23: CP-DUMASTIC_(20KG_PAIL) | G23: DUMASTIC (20KG PAIL) | H23: 32 | I23: 32 | J23: 0 | K23: Nos | L23: {=IFERROR( _xlfn.TEXTJOIN(CHAR(10),TRUE, _xlfn._xlws.FILTER( "Name: "&'Master Data'!$J$2:$J$10000& " Price: "&'Master Data'!$L$2:$L$10000& " Qty: "&('Master Data'!$K$2:$K$10000-'Master Data'!$Q$2:$Q$10000)& " Unit: "&'Master Data'!$N$2:$N$10000& " Supplier Reference: "&'Master Data'!$B$2:$B$10000& " PO Reference: "&'Master Data'!$A$2:$A$10000, ('Master Data'!$J$2:$J$10000=D23)* (('Master Data'!$K$2:$K$10000-'Master Data'!$Q$2:$Q$10000)<>0) ) ), "Not Found")} -> Name: DUMASTIC 20 KG Price: 115 Qty: 30 Unit: PAIL Supplier Reference: MR MD For Project Management Services EST PO Reference: PUR-ORD-2026-00049 Name: DUMASTIC 20 KG Price: 115 Qty: 2 Unit: PAIL Supplier Reference: MR MD For Project Management Services EST PO Reference: PUR-ORD-2026-00049 | M23: Stores - MRG
B24: Duproof L.L.C | C24: DUPLAST P-MEMBRANE 4MM 1M X 10 MTR ROLL | D24: DUPLAST P-MEMBRANE 4MM 1M X 10 MTR ROLL | E24: Match | F24: CP-DUPLAST_P_MEMBRANE_4MM___(1M*10M_ROLL) | G24: DUPLAST P-MEMBRANE 4MM (1M*10M ROLL) | H24: 112 | I24: 112 | J24: 0 | K24: Nos | L24: {=IFERROR( _xlfn.TEXTJOIN(CHAR(10),TRUE, _xlfn._xlws.FILTER( "Name: "&'Master Data'!$J$2:$J$10000& " Price: "&'Master Data'!$L$2:$L$10000& " Qty: "&('Master Data'!$K$2:$K$10000-'Master Data'!$Q$2:$Q$10000)& " Unit: "&'Master Data'!$N$2:$N$10000& " Supplier Reference: "&'Master Data'!$B$2:$B$10000& " PO Reference: "&'Master Data'!$A$2:$A$10000, ('Master Data'!$J$2:$J$10000=D24)* (('Master Data'!$K$2:$K$10000-'Master Data'!$Q$2:$Q$10000)<>0) ) ), "Not Found")} -> Name: DUPLAST P-MEMBRANE 4MM 1M X 10 MTR ROLL Price: 144 Qty: 112 Unit: ROLL Supplier Reference: MR MD For Project Management Services EST PO Reference: PUR-ORD-2026-00049 | M24: Stores - MRG
A25: MRG-LPO-00045-1 | B25: GEOBIT INDUSTRIES L.L.C | C25: BETOFLEX PU-POLY BETOL 220 KG | D25: BETOFLEX PU-POLY BETOL 220 KG | E25: Match | F25: CP-BETOFLEX_PU_PPLY_BETOL_220KG_DRUM) | G25: BETOFLEX PU-PPLY BETOL 220KG DRUM) | H25: 20 | I25: 20 | J25: 0 | K25: Nos | L25: {=IFERROR( _xlfn.TEXTJOIN(CHAR(10),TRUE, _xlfn._xlws.FILTER( "Name: "&'Master Data'!$J$2:$J$10000& " Price: "&'Master Data'!$L$2:$L$10000& " Qty: "&('Master Data'!$K$2:$K$10000-'Master Data'!$Q$2:$Q$10000)& " Unit: "&'Master Data'!$N$2:$N$10000& " Supplier Reference: "&'Master Data'!$B$2:$B$10000& " PO Reference: "&'Master Data'!$A$2:$A$10000, ('Master Data'!$J$2:$J$10000=D25)* (('Master Data'!$K$2:$K$10000-'Master Data'!$Q$2:$Q$10000)<>0) ) ), "Not Found")} -> Name: BETOFLEX PU-POLY BETOL 220 KG Price: 1892 Qty: 20 Unit: Kg Supplier Reference: MR MD For Project Management Services EST PO Reference: PUR-ORD-2026-00049 | M25: Stores - MRG
B26: GEOBIT INDUSTRIES L.L.C | C26: BETOFLEX PU-ISO BETOL 250 KG | D26: BETOFLEX PU-ISO BETOL 250 KG | E26: Match | F26: CP-BETOFLEX_PU_ISO_BETOL_(250KG_DRUM) | G26: BETOFLEX PU-ISO BETOL (250KG DRUM) | H26: 20 | I26: 20 | J26: 0 | K26: Nos | L26: {=IFERROR( _xlfn.TEXTJOIN(CHAR(10),TRUE, _xlfn._xlws.FILTER( "Name: "&'Master Data'!$J$2:$J$10000& " Price: "&'Master Data'!$L$2:$L$10000& " Qty: "&('Master Data'!$K$2:$K$10000-'Master Data'!$Q$2:$Q$10000)& " Unit: "&'Master Data'!$N$2:$N$10000& " Supplier Reference: "&'Master Data'!$B$2:$B$10000& " PO Reference: "&'Master Data'!$A$2:$A$10000, ('Master Data'!$J$2:$J$10000=D26)* (('Master Data'!$K$2:$K$10000-'Master Data'!$Q$2:$Q$10000)<>0) ) ), "Not Found")} -> Name: BETOFLEX PU-ISO BETOL 250 KG Price: 2150 Qty: 20 Unit: Kg Supplier Reference: MR MD For Project Management Services EST PO Reference: PUR-ORD-2026-00049 | M26: Stores - MRG
B27: GEOBIT INDUSTRIES L.L.C | C27: BETOFLEX 4P | D27: BETOFLEX 4P | E27: Match | F27: CP-BETOFLEX_4P_(1*10_MTR_ROLL) | G27: BETOFLEX 4P (1*10 MTR ROLL) | H27: 460 | I27: 460 | J27: 0 | K27: Nos | L27: {=IFERROR( _xlfn.TEXTJOIN(CHAR(10),TRUE, _xlfn._xlws.FILTER( "Name: "&'Master Data'!$J$2:$J$10000& " Price: "&'Master Data'!$L$2:$L$10000& " Qty: "&('Master Data'!$K$2:$K$10000-'Master Data'!$Q$2:$Q$10000)& " Unit: "&'Master Data'!$N$2:$N$10000& " Supplier Reference: "&'Master Data'!$B$2:$B$10000& " PO Reference: "&'Master Data'!$A$2:$A$10000, ('Master Data'!$J$2:$J$10000=D27)* (('Master Data'!$K$2:$K$10000-'Master Data'!$Q$2:$Q$10000)<>0) ) ), "Not Found")} -> Name: BETOFLEX 4P Price: 110 Qty: 460 Unit: M2 Supplier Reference: MR MD For Project Management Services EST PO Reference: PUR-ORD-2026-00049 | M27: Stores - MRG
A28: MRG-LPO-00197 | B28: GREEN FUSION COMPUTER TRADING LLC | C28: PRINTER | D28: PRINTER | E28: Match | F28: CP-LEASE_CHARGES_FOR_PRINTER_(MONTHLY) | G28: LEASE CHARGES FOR PRINTER (MONTHLY) | H28: 2 | I28: 2 | J28: 0 | K28: Nos | L28: {=IFERROR( _xlfn.TEXTJOIN(CHAR(10),TRUE, _xlfn._xlws.FILTER( "Name: "&'Master Data'!$J$2:$J$10000& " Price: "&'Master Data'!$L$2:$L$10000& " Qty: "&('Master Data'!$K$2:$K$10000-'Master Data'!$Q$2:$Q$10000)& " Unit: "&'Master Data'!$N$2:$N$10000& " Supplier Reference: "&'Master Data'!$B$2:$B$10000& " PO Reference: "&'Master Data'!$A$2:$A$10000, ('Master Data'!$J$2:$J$10000=D28)* (('Master Data'!$K$2:$K$10000-'Master Data'!$Q$2:$Q$10000)<>0) ) ), "Not Found")} -> Name: PRINTER Price: 420 Qty: 1 Unit: Months Supplier Reference: GREEN FUSION COMPUTER TRADING LLC PO Reference: MRG-LPO-00197 Name: PRINTER Price: 350 Qty: 1 Unit: Months Supplier Reference: MR MD For Project Management Services EST PO Reference: PUR-ORD-2026-00049 | M28: Stores - MRG
A29: MRG-LPO-00056, MRG-LPO-00277, MRG-LPO-00307-1, MRG-LPO-00545, MRG-LPO-00588, PUR-ORD-2026-00018 | B29: GS ENTERPRISES FZ LLC | C29: NW 120 GSM PET -WHITE (3 MTR *100 MTR) | D29: NW 120 GSM PET -WHITE (3 MTR *100 MTR) | E29: Match | F29: CP-NW_120_GSM_PET__WHITE_(3_M_*100_M) | G29: NW 120 GSM PET -WHITE (3 M *100 M) | H29: 18 | I29: 18 | J29: 0 | K29: Nos | L29: {=IFERROR( _xlfn.TEXTJOIN(CHAR(10),TRUE, _xlfn._xlws.FILTER( "Name: "&'Master Data'!$J$2:$J$10000& " Price: "&'Master Data'!$L$2:$L$10000& " Qty: "&('Master Data'!$K$2:$K$10000-'Master Data'!$Q$2:$Q$10000)& " Unit: "&'Master Data'!$N$2:$N$10000& " Supplier Reference: "&'Master Data'!$B$2:$B$10000& " PO Reference: "&'Master Data'!$A$2:$A$10000, ('Master Data'!$J$2:$J$10000=D29)* (('Master Data'!$K$2:$K$10000-'Master Data'!$Q$2:$Q$10000)<>0) ) ), "Not Found")} -> Name: NW 120 GSM PET -WHITE (3 MTR *100 MTR) Price: 305 Qty: 1 Unit: M2 Supplier Reference: GS ENTERPRISES FZ LLC PO Reference: MRG-LPO-00056 Name: NW 120 GSM PET -WHITE (3 MTR *100 MTR) Price: 335 Qty: 10 Unit: M2 Supplier Reference: GS ENTERPRISES FZ LLC PO Reference: MRG-LPO-00277 Name: NW 120 GSM PET -WHITE (3 MTR *100 MTR) Price: 335 Qty: 7 Unit: M2 Supplier Reference: GS ENTERPRISES FZ LLC PO Reference: MRG-LPO-00307-1 | M29: Stores - MRG
B30: GS ENTERPRISES FZ LLC | C30: NW 250 GSM PET -WHITE (3 MTR *100 MTR) | D30: NW 250 GSM PET -WHITE (3 MTR *100 MTR) | E30: Match | F30: CP-NW_250_GSM_PET__WHITE_(3_M_*100_M) | G30: NW 250 GSM PET -WHITE (3 M *100 M) | H30: 80 | I30: 80 | J30: 0 | K30: Nos | L30: {=IFERROR( _xlfn.TEXTJOIN(CHAR(10),TRUE, _xlfn._xlws.FILTER( "Name: "&'Master Data'!$J$2:$J$10000& " Price: "&'Master Data'!$L$2:$L$10000& " Qty: "&('Master Data'!$K$2:$K$10000-'Master Data'!$Q$2:$Q$10000)& " Unit: "&'Master Data'!$N$2:$N$10000& " Supplier Reference: "&'Master Data'!$B$2:$B$10000& " PO Reference: "&'Master Data'!$A$2:$A$10000, ('Master Data'!$J$2:$J$10000=D30)* (('Master Data'!$K$2:$K$10000-'Master Data'!$Q$2:$Q$10000)<>0) ) ), "Not Found")} -> Name: NW 250 GSM PET -WHITE (3 MTR *100 MTR) Price: 745 Qty: 50 Unit: M2 Supplier Reference: MR MD For Project Management Services EST PO Reference: PUR-ORD-2026-00049 Name: NW 250 GSM PET -WHITE (3 MTR *100 MTR) Price: 560 Qty: 30 Unit: M2 Supplier Reference: MR MD For Project Management Services EST PO Reference: PUR-ORD-2026-00049 | M30: Stores - MRG
A31: MRG-LPO-00017, MRG-LPO-00057 | B31: HUNTSMAN UAE FZE | C31: HUNSTMAN SP 45 (220KG) DRUM | D31: HUNSTMAN SP 45 (220KG) DRUM | E31: Match | F31: CP-HUNTSMAN_SP_45_(220KG_DRUM) | G31: HUNTSMAN SP 45 (220KG DRUM) | H31: 2640 | I31: 12 | J31: -2628 | K31: Nos | L31: {=IFERROR( _xlfn.TEXTJOIN(CHAR(10),TRUE, _xlfn._xlws.FILTER( "Name: "&'Master Data'!$J$2:$J$10000& " Price: "&'Master Data'!$L$2:$L$10000& " Qty: "&('Master Data'!$K$2:$K$10000-'Master Data'!$Q$2:$Q$10000)& " Unit: "&'Master Data'!$N$2:$N$10000& " Supplier Reference: "&'Master Data'!$B$2:$B$10000& " PO Reference: "&'Master Data'!$A$2:$A$10000, ('Master Data'!$J$2:$J$10000=D31)* (('Master Data'!$K$2:$K$10000-'Master Data'!$Q$2:$Q$10000)<>0) ) ), "Not Found")} -> Name: HUNSTMAN SP 45 (220KG) DRUM Price: 10.5 Qty: 2640 Unit: Kg Supplier Reference: HUNTSMAN UAE FZE PO Reference: MRG-LPO-00057 | M31: Stores - MRG
B32: HUNTSMAN UAE FZE | C32: HUNSTMAN 200 (250KG) DRUM | D32: HUNSTMAN 200 (250KG) DRUM | E32: Match | F32: CP-HUNTSMAN_200_(250KG_DRUM) | G32: HUNTSMAN 200 (250KG DRUM) | H32: 3000 | I32: 12 | J32: -2988 | K32: Nos | L32: {=IFERROR( _xlfn.TEXTJOIN(CHAR(10),TRUE, _xlfn._xlws.FILTER( "Name: "&'Master Data'!$J$2:$J$10000& " Price: "&'Master Data'!$L$2:$L$10000& " Qty: "&('Master Data'!$K$2:$K$10000-'Master Data'!$Q$2:$Q$10000)& " Unit: "&'Master Data'!$N$2:$N$10000& " Supplier Reference: "&'Master Data'!$B$2:$B$10000& " PO Reference: "&'Master Data'!$A$2:$A$10000, ('Master Data'!$J$2:$J$10000=D32)* (('Master Data'!$K$2:$K$10000-'Master Data'!$Q$2:$Q$10000)<>0) ) ), "Not Found")} -> Name: HUNSTMAN 200 (250KG) DRUM Price: 10.5 Qty: 3000 Unit: Kg Supplier Reference: MR MD For Project Management Services EST PO Reference: PUR-ORD-2026-00049 | M32: Stores - MRG
A33: MRG-LPO-00607 | B33: IRSHAD KASHIM AND MOHAMMED AMEER STATIONERY LLC | C33: Box File -PVC (Green) | D33: Box File -PVC (Green) | E33: Match | F33: CP-BOX_FILE__PVC_(GREEN) | G33: BOX FILE -PVC (GREEN) | H33: 1 | I33: 1 | J33: 0 | K33: CTN | L33: {=IFERROR( _xlfn.TEXTJOIN(CHAR(10),TRUE, _xlfn._xlws.FILTER( "Name: "&'Master Data'!$J$2:$J$10000& " Price: "&'Master Data'!$L$2:$L$10000& " Qty: "&('Master Data'!$K$2:$K$10000-'Master Data'!$Q$2:$Q$10000)& " Unit: "&'Master Data'!$N$2:$N$10000& " Supplier Reference: "&'Master Data'!$B$2:$B$10000& " PO Reference: "&'Master Data'!$A$2:$A$10000, ('Master Data'!$J$2:$J$10000=D33)* (('Master Data'!$K$2:$K$10000-'Master Data'!$Q$2:$Q$10000)<>0) ) ), "Not Found")} -> Name: Box File -PVC (Green) Price: 235 Qty: 1 Unit: CTN Supplier Reference: IRSHAD KASHIM AND MOHAMMED AMEER STATIONERY LLC PO Reference: MRG-LPO-00607 | M33: Stores - MRG
B34: IRSHAD KASHIM AND MOHAMMED AMEER STATIONERY LLC | C34: WHITE BOARD MARKER | D34: WHITE BOARD MARKER | E34: Match | F34: CP-WHITE_BOARD__MARKER | G34: WHITE BOARD MARKER | H34: 1 | I34: 1 | J34: 0 | K34: Nos | L34: {=IFERROR( _xlfn.TEXTJOIN(CHAR(10),TRUE, _xlfn._xlws.FILTER( "Name: "&'Master Data'!$J$2:$J$10000& " Price: "&'Master Data'!$L$2:$L$10000& " Qty: "&('Master Data'!$K$2:$K$10000-'Master Data'!$Q$2:$Q$10000)& " Unit: "&'Master Data'!$N$2:$N$10000& " Supplier Reference: "&'Master Data'!$B$2:$B$10000& " PO Reference: "&'Master Data'!$A$2:$A$10000, ('Master Data'!$J$2:$J$10000=D34)* (('Master Data'!$K$2:$K$10000-'Master Data'!$Q$2:$Q$10000)<>0) ) ), "Not Found")} -> Name: WHITE BOARD MARKER Price: 15 Qty: 1 Unit: Nos Supplier Reference: MR MD For Project Management Services EST PO Reference: PUR-ORD-2026-00049 | M34: Stores - MRG
B35: IRSHAD KASHIM AND MOHAMMED AMEER STATIONERY LLC | C35: Highlighter Assorted Color(5 Pcs/Pkt) | D35: Highlighter Assorted Color(5 Pcs/Pkt) | E35: Match | F35: Highlighter Assorted Color(5 Pcs/Pkt) | G35: Highlighter Assorted Color(5 Pcs/Pkt) | H35: 1 | I35: 1 | J35: 0 | K35: PKT | L35: {=IFERROR( _xlfn.TEXTJOIN(CHAR(10),TRUE, _xlfn._xlws.FILTER( "Name: "&'Master Data'!$J$2:$J$10000& " Price: "&'Master Data'!$L$2:$L$10000& " Qty: "&('Master Data'!$K$2:$K$10000-'Master Data'!$Q$2:$Q$10000)& " Unit: "&'Master Data'!$N$2:$N$10000& " Supplier Reference: "&'Master Data'!$B$2:$B$10000& " PO Reference: "&'Master Data'!$A$2:$A$10000, ('Master Data'!$J$2:$J$10000=D35)* (('Master Data'!$K$2:$K$10000-'Master Data'!$Q$2:$Q$10000)<>0) ) ), "Not Found")} -> Name: Highlighter Assorted Color(5 Pcs/Pkt) Price: 18 Qty: 1 Unit: PKT Supplier Reference: MR MD For Project Management Services EST PO Reference: PUR-ORD-2026-00049 | M35: Stores - MRG
B36: IRSHAD KASHIM AND MOHAMMED AMEER STATIONERY LLC | C36: Stapler | D36: STAPLER | E36: Match | F36: STAPLER PIN 20 PKT / BOX | G36: STAPLER PIN 20 PKT / BOX | H36: 2 | I36: 2 | J36: 0 | K36: Box | L36: {=IFERROR( _xlfn.TEXTJOIN(CHAR(10),TRUE, _xlfn._xlws.FILTER( "Name: "&'Master Data'!$J$2:$J$10000& " Price: "&'Master Data'!$L$2:$L$10000& " Qty: "&('Master Data'!$K$2:$K$10000-'Master Data'!$Q$2:$Q$10000)& " Unit: "&'Master Data'!$N$2:$N$10000& " Supplier Reference: "&'Master Data'!$B$2:$B$10000& " PO Reference: "&'Master Data'!$A$2:$A$10000, ('Master Data'!$J$2:$J$10000=D36)* (('Master Data'!$K$2:$K$10000-'Master Data'!$Q$2:$Q$10000)<>0) ) ), "Not Found")} -> Name: STAPLER Price: 12 Qty: 2 Unit: Nos Supplier Reference: MR MD For Project Management Services EST PO Reference: PUR-ORD-2026-00049 | M36: Stores - MRG
B37: IRSHAD KASHIM AND MOHAMMED AMEER STATIONERY LLC | C37: PEN KRISH | D37: PEN KRISH | E37: Match | F37: CP-KRISH_BALL_PEN_RED_(50PCS/PKT) | G37: KRISH BALL PEN RED (50PCS/PKT) | H37: 2 | I37: 2 | J37: 0 | K37: Nos | L37: {=IFERROR( _xlfn.TEXTJOIN(CHAR(10),TRUE, _xlfn._xlws.FILTER( "Name: "&'Master Data'!$J$2:$J$10000& " Price: "&'Master Data'!$L$2:$L$10000& " Qty: "&('Master Data'!$K$2:$K$10000-'Master Data'!$Q$2:$Q$10000)& " Unit: "&'Master Data'!$N$2:$N$10000& " Supplier Reference: "&'Master Data'!$B$2:$B$10000& " PO Reference: "&'Master Data'!$A$2:$A$10000, ('Master Data'!$J$2:$J$10000=D37)* (('Master Data'!$K$2:$K$10000-'Master Data'!$Q$2:$Q$10000)<>0) ) ), "Not Found")} -> Name: PEN KRISH Price: 42 Qty: 2 Unit: PKT Supplier Reference: MR MD For Project Management Services EST PO Reference: PUR-ORD-2026-00049 | M37: Stores - MRG
B38: IRSHAD KASHIM AND MOHAMMED AMEER STATIONERY LLC | C38: PAPER CLIP | D38: PAPER CLIP | E38: Match | F38: CP-PAPER_CLIP_233_(10_PKT/BOX) | G38: PAPER CLIP 233 (10 PKT/BOX) | H38: 2 | I38: 2 | J38: 0 | K38: Nos | L38: {=IFERROR( _xlfn.TEXTJOIN(CHAR(10),TRUE, _xlfn._xlws.FILTER( "Name: "&'Master Data'!$J$2:$J$10000& " Price: "&'Master Data'!$L$2:$L$10000& " Qty: "&('Master Data'!$K$2:$K$10000-'Master Data'!$Q$2:$Q$10000)& " Unit: "&'Master Data'!$N$2:$N$10000& " Supplier Reference: "&'Master Data'!$B$2:$B$10000& " PO Reference: "&'Master Data'!$A$2:$A$10000, ('Master Data'!$J$2:$J$10000=D38)* (('Master Data'!$K$2:$K$10000-'Master Data'!$Q$2:$Q$10000)<>0) ) ), "Not Found")} -> Name: PAPER CLIP Price: 20 Qty: 1 Unit: Nos Supplier Reference: MR MD For Project Management Services EST PO Reference: PUR-ORD-2026-00049 Name: PAPER CLIP Price: 55 Qty: 1 Unit: Nos Supplier Reference: MR MD For Project Management Services EST PO Reference: PUR-ORD-2026-00049 | M38: Stores - MRG
B39: IRSHAD KASHIM AND MOHAMMED AMEER STATIONERY LLC | C39: ERASER | D39: ERASER | E39: Match | F39: ERASER | G39: ERASER | H39: 10 | I39: 10 | J39: 0 | K39: Nos | L39: {=IFERROR( _xlfn.TEXTJOIN(CHAR(10),TRUE, _xlfn._xlws.FILTER( "Name: "&'Master Data'!$J$2:$J$10000& " Price: "&'Master Data'!$L$2:$L$10000& " Qty: "&('Master Data'!$K$2:$K$10000-'Master Data'!$Q$2:$Q$10000)& " Unit: "&'Master Data'!$N$2:$N$10000& " Supplier Reference: "&'Master Data'!$B$2:$B$10000& " PO Reference: "&'Master Data'!$A$2:$A$10000, ('Master Data'!$J$2:$J$10000=D39)* (('Master Data'!$K$2:$K$10000-'Master Data'!$Q$2:$Q$10000)<>0) ) ), "Not Found")} -> Name: ERASER Price: 2 Qty: 10 Unit: Nos Supplier Reference: MR MD For Project Management Services EST PO Reference: PUR-ORD-2026-00049 | M39: Stores - MRG
B40: IRSHAD KASHIM AND MOHAMMED AMEER STATIONERY LLC | C40: Divider 1-12 | D40: Divider 1-12 | E40: Match | F40: CP-DIVIDER_01___12_(30_SETS/BOX) | G40: DIVIDER 01 - 12 (30 SETS/BOX) | H40: 3 | I40: 3 | J40: 0 | K40: Nos | L40: {=IFERROR( _xlfn.TEXTJOIN(CHAR(10),TRUE, _xlfn._xlws.FILTER( "Name: "&'Master Data'!$J$2:$J$10000& " Price: "&'Master Data'!$L$2:$L$10000& " Qty: "&('Master Data'!$K$2:$K$10000-'Master Data'!$Q$2:$Q$10000)& " Unit: "&'Master Data'!$N$2:$N$10000& " Supplier Reference: "&'Master Data'!$B$2:$B$10000& " PO Reference: "&'Master Data'!$A$2:$A$10000, ('Master Data'!$J$2:$J$10000=D40)* (('Master Data'!$K$2:$K$10000-'Master Data'!$Q$2:$Q$10000)<>0) ) ), "Not Found")} -> Name: Divider 1-12 Price: 120 Qty: 3 Unit: Box Supplier Reference: MR MD For Project Management Services EST PO Reference: PUR-ORD-2026-00049 | M40: Stores - MRG
...

Sheet Master Data
A1: ID | B1: Supplier | C1: Date | D1: Company | E1: Currency | F1: Exchange Rate | G1: Status | H1: Amount (Company Currency) (Items) | I1: Item Code (Items) | J1: Item Name (Items) | K1: Quantity (Items) | L1: Rate (Company Currency) (Items) | M1: Required By (Items) | N1: Stock UOM (Items) | O1: UOM (Items) | P1: UOM Conversion Factor (Items) | Q1: Received Qty (Items)
A2: MRG-LPO-00022 | B2: AJMAN GAS LLC | C2: 45904 | D2: M R G INSULATION WORKS L.L.C | E2: AED | F2: 1 | G2: To Receive and Bill | H2: 13420 | I2: WATERPRROFING GAS (22KG) | J2: WATERPRROFING GAS 22 KG | K2: 122 | L2: 110 | M2: 46387 | N2: CYLINDER | O2: CYLINDER | P2: 1 | Q2: 108
A3: MRG-LPO-00016 | B3: SIKA UAE LLC | C3: 45971 | D3: M R G INSULATION WORKS L.L.C | E3: AED | F3: 1 | G3: To Receive and Bill | H3: 207000 | I3: SIKA SHIELD P26 MG SA 4MM ROLL 1MX10M | J3: SIKA SHIELD P26 MG SA 4MM ROLL 1MX10M | K3: 1800 | L3: 115 | M3: 46112 | N3: M2 | O3: ROLL | P3: 10 | Q3: 23
A4: PUR-ORD-2025-00005 | B4: AWAZEL INTERNATIONAL CO LLC | C4: 45996 | D4: M R G INSULATION WORKS L.L.C | E4: AED | F4: 1 | G4: To Receive and Bill | H4: 32292 | I4: PY40200L BSP 10 M MEMBRANE SBS MODIFIED 200G | J4: PY40200L BSP 10 M MEMBRANE SBS MODIFIED 200G | K4: 276 | L4: 117 | M4: 46022 | N4: M2 | O4: ROLL | P4: 10 | Q4: 0
A5: PUR-ORD-2025-00006 | B5: SIKA UAE LLC | C5: 45996 | D5: M R G INSULATION WORKS L.L.C | E5: AED | F5: 1 | G5: To Receive and Bill | H5: 6800 | I5: SIKABIT P -12 AE BITUMENIOUS PRIMER (180KG) DRUM | J5: SIKABIT P -12 AE BITUMENIOUS PRIMER (180KG) DRUM | K5: 8 | L5: 850 | M5: 46022 | N5: Kg | O5: DRUM | P5: 180 | Q5: 0
A6: PUR-ORD-2025-00007 | B6: SHAHERA STEEL & WELDING W/SHOP | C6: 45996 | D6: M R G INSULATION WORKS L.L.C | E6: AED | F6: 1 | G6: To Receive and Bill | H6: 1700 | I6: DEEP TRAY FOR DIESEL DRUMS ( 4 DRUMS ) | J6: DEEP TRAY FOR DIESEL DRUMS | K6: 2 | L6: 850 | M6: 46022 | N6: Nos | O6: Nos | P6: 1 | Q6: 0
A7: PUR-ORD-2025-00008 | B7: AWAZEL INTERNATIONAL CO LLC | C7: 45997 | D7: M R G INSULATION WORKS L.L.C | E7: AED | F7: 1 | G7: To Receive and Bill | H7: 26910 | I7: PY40200L BSP 10 M MEMBRANE SBS MODIFIED 200G | J7: PY40200L BSP 10 M MEMBRANE SBS MODIFIED 200G | K7: 230 | L7: 117 | M7: 46022 | N7: M2 | O7: ROLL | P7: 10 | Q7: 0
A8: PUR-ORD-2025-00011 | B8: Al Gurg Fosroc LLC | C8: 45998 | D8: M R G INSULATION WORKS L.L.C | E8: AED | F8: 1 | G8: To Receive and Bill | H8: 2600 | I8: PROTECTION BOARD (6MMX2MX1M) SHEET | J8: PROTECTION BOARD (6MMX2MX1M) SHEET | K8: 80 | L8: 32.5 | M8: 46022 | N8: Nos | O8: SHEET | P8: 1 | Q8: 0
A9: PUR-ORD-2025-00009 | B9: SHERIDAN SPECIALIZED BUILDING PRODUCTS L.L.C | C9: 45999 | D9: M R G INSULATION WORKS L.L.C | E9: AED | F9: 1 | G9: To Receive and Bill | H9: 49200 | I9: NEONATE MDI (250KG) DRUM | J9: NEONATE MDI (250KG) DRUM | K9: 24 | L9: 2050 | M9: 46022 | N9: Kg | O9: DRUM | P9: 250 | Q9: 10
A10: PUR-ORD-2025-00013 | B10: Al Nawras Printing Press Services | C10: 46000 | D10: M R G INSULATION WORKS L.L.C | E10: AED | F10: 1 | G10: To Receive and Bill | H10: 700 | I10: LETTER HEAD KLNNARI OFFWHITE FULL COLOR PRINTING | J10: LETTER HEAD KLNNARI OFFWHITE FULL COLOR PRINTING | K10: 1000 | L10: 0.7 | M10: 46022 | N10: Nos | O10: Nos | P10: 1 | Q10: 0
A11: PUR-ORD-2025-00016 | B11: AL YASIN EQUIPMENT RENTAL LLC | C11: 46001 | D11: M R G INSULATION WORKS L.L.C | E11: AED | F11: 1 | G11: To Receive and Bill | H11: 720 | I11: HIRE OF POWER FLOAT | J11: HIRE OF POWER FLOAT | K11: 12 | L11: 60 | M11: 46022 | N11: Day | O11: Day | P11: 1 | Q11: 0
A12: PUR-ORD-2025-00018 | B12: THREE STAR EQUIPMET RENTAL L.L.C | C12: 46001 | D12: M R G INSULATION WORKS L.L.C | E12: AED | F12: 1 | G12: To Receive and Bill | H12: 240 | I12: HIRE OF POWER FLOAT | J12: HIRE OF POWER FLOAT | K12: 4 | L12: 60 | M12: 46022 | N12: Day | O12: Day | P12: 1 | Q12: 0
A13: PUR-ORD-2025-00015-1 | B13: SHINGAK PASSENGERS TRANSPORT BY RENTED BUSES LLC | C13: 46001 | D13: M R G INSULATION WORKS L.L.C | E13: AED | F13: 1 | G13: To Receive and Bill | H13: 8000 | I13: HIRE 66 SEATER BUS WITH DRIVER & WITH FUEL | J13: 66 SEATER BUS WITH DRIVER & FUEL | K13: 1 | L13: 8000 | M13: 46022 | N13: Nos | O13: Nos | P13: 1 | Q13: 0
... A210: PUR-ORD-2026-00049 | B210: MR MD For Project Management Services EST | C210: 46317 | D210: M R G INSULATION WORKS L.L.C | E210: AED | F210: 1 | G210: To Receive and Bill | H210: 3 | I210: CP-APPLICATION_OF_ANGLE_FILLET_WITH_MESH | J210: Application of angle fillet with mesh | K210: 1 | L210: 3 | M210: 46317 | N210: M2 | O210: M2 | P210: 1 | Q210: 0
